2024-10-09 08:55:38,739 ERROR: Exception on /forgot-password [POST] [in /Users/austinheywood/source/flask-auth-starter/venv/lib/python3.11/site-packages/flask/app.py:838]
Traceback (most recent call last):
  File "/Users/austinheywood/source/flask-auth-starter/venv/lib/python3.11/site-packages/flask/app.py", line 1473, in wsgi_app
    response = self.full_dispatch_request()
               ^^^^^^^^^^^^^^^^^^^^^^^^^^^^
  File "/Users/austinheywood/source/flask-auth-starter/venv/lib/python3.11/site-packages/flask/app.py", line 882, in full_dispatch_request
    rv = self.handle_user_exception(e)
         ^^^^^^^^^^^^^^^^^^^^^^^^^^^^^
  File "/Users/austinheywood/source/flask-auth-starter/venv/lib/python3.11/site-packages/flask/app.py", line 880, in full_dispatch_request
    rv = self.dispatch_request()
         ^^^^^^^^^^^^^^^^^^^^^^^
  File "/Users/austinheywood/source/flask-auth-starter/venv/lib/python3.11/site-packages/flask/app.py", line 865, in dispatch_request
    return self.ensure_sync(self.view_functions[rule.endpoint])(**view_args)  # type: ignore[no-any-return]
           ^^^^^^^^^^^^^^^^^^^^^^^^^^^^^^^^^^^^^^^^^^^^^^^^^^^^^^^^^^^^^^^^^
  File "/Users/austinheywood/source/flask-auth-starter/app/auth/routes.py", line 204, in forgot_password
    send_password_reset_email(user.email, reset_url)
TypeError: send_password_reset_email() takes 1 positional argument but 2 were given
2024-10-09 08:55:43,044 ERROR: Exception on /forgot-password [POST] [in /Users/austinheywood/source/flask-auth-starter/venv/lib/python3.11/site-packages/flask/app.py:838]
Traceback (most recent call last):
  File "/Users/austinheywood/source/flask-auth-starter/venv/lib/python3.11/site-packages/flask/app.py", line 1473, in wsgi_app
    response = self.full_dispatch_request()
               ^^^^^^^^^^^^^^^^^^^^^^^^^^^^
  File "/Users/austinheywood/source/flask-auth-starter/venv/lib/python3.11/site-packages/flask/app.py", line 882, in full_dispatch_request
    rv = self.handle_user_exception(e)
         ^^^^^^^^^^^^^^^^^^^^^^^^^^^^^
  File "/Users/austinheywood/source/flask-auth-starter/venv/lib/python3.11/site-packages/flask/app.py", line 880, in full_dispatch_request
    rv = self.dispatch_request()
         ^^^^^^^^^^^^^^^^^^^^^^^
  File "/Users/austinheywood/source/flask-auth-starter/venv/lib/python3.11/site-packages/flask/app.py", line 865, in dispatch_request
    return self.ensure_sync(self.view_functions[rule.endpoint])(**view_args)  # type: ignore[no-any-return]
           ^^^^^^^^^^^^^^^^^^^^^^^^^^^^^^^^^^^^^^^^^^^^^^^^^^^^^^^^^^^^^^^^^
  File "/Users/austinheywood/source/flask-auth-starter/app/auth/routes.py", line 204, in forgot_password
    send_password_reset_email(user.email, reset_url)
TypeError: send_password_reset_email() takes 1 positional argument but 2 were given
2024-10-09 08:57:52,391 INFO: Flask Auth Starter startup [in /Users/austinheywood/source/flask-auth-starter/app/__init__.py:60]
2024-10-09 08:57:57,343 ERROR: Exception on /forgot-password [POST] [in /Users/austinheywood/source/flask-auth-starter/venv/lib/python3.11/site-packages/flask/app.py:838]
Traceback (most recent call last):
  File "/Users/austinheywood/source/flask-auth-starter/venv/lib/python3.11/site-packages/flask/app.py", line 1473, in wsgi_app
    response = self.full_dispatch_request()
               ^^^^^^^^^^^^^^^^^^^^^^^^^^^^
  File "/Users/austinheywood/source/flask-auth-starter/venv/lib/python3.11/site-packages/flask/app.py", line 882, in full_dispatch_request
    rv = self.handle_user_exception(e)
         ^^^^^^^^^^^^^^^^^^^^^^^^^^^^^
  File "/Users/austinheywood/source/flask-auth-starter/venv/lib/python3.11/site-packages/flask/app.py", line 880, in full_dispatch_request
    rv = self.dispatch_request()
         ^^^^^^^^^^^^^^^^^^^^^^^
  File "/Users/austinheywood/source/flask-auth-starter/venv/lib/python3.11/site-packages/flask/app.py", line 865, in dispatch_request
    return self.ensure_sync(self.view_functions[rule.endpoint])(**view_args)  # type: ignore[no-any-return]
           ^^^^^^^^^^^^^^^^^^^^^^^^^^^^^^^^^^^^^^^^^^^^^^^^^^^^^^^^^^^^^^^^^
  File "/Users/austinheywood/source/flask-auth-starter/app/auth/routes.py", line 204, in forgot_password
    send_password_reset_email(user.email, reset_url)
  File "/Users/austinheywood/source/flask-auth-starter/app/email.py", line 24, in send_password_reset_email
    text_body = render_template('email/auth_reset-pass.txt',
                ^^^^^^^^^^^^^^^^^^^^^^^^^^^^^^^^^^^^^^^^^^^^
  File "/Users/austinheywood/source/flask-auth-starter/venv/lib/python3.11/site-packages/flask/templating.py", line 150, in render_template
    return _render(app, template, context)
           ^^^^^^^^^^^^^^^^^^^^^^^^^^^^^^^
  File "/Users/austinheywood/source/flask-auth-starter/venv/lib/python3.11/site-packages/flask/templating.py", line 131, in _render
    rv = template.render(context)
         ^^^^^^^^^^^^^^^^^^^^^^^^
  File "/Users/austinheywood/source/flask-auth-starter/venv/lib/python3.11/site-packages/jinja2/environment.py", line 1304, in render
    self.environment.handle_exception()
  File "/Users/austinheywood/source/flask-auth-starter/venv/lib/python3.11/site-packages/jinja2/environment.py", line 939, in handle_exception
    raise rewrite_traceback_stack(source=source)
  File "/Users/austinheywood/source/flask-auth-starter/app/templates/email/auth_reset-pass.txt", line 1, in top-level template code
    Dear {{ user.email }},
  File "/Users/austinheywood/source/flask-auth-starter/venv/lib/python3.11/site-packages/jinja2/environment.py", line 487, in getattr
    return getattr(obj, attribute)
           ^^^^^^^^^^^^^^^^^^^^^^^
jinja2.exceptions.UndefinedError: 'user' is undefined
2024-10-09 08:58:41,060 INFO: Flask Auth Starter startup [in /Users/austinheywood/source/flask-auth-starter/app/__init__.py:60]
2024-10-09 08:58:47,684 ERROR: Exception on /forgot-password [POST] [in /Users/austinheywood/source/flask-auth-starter/venv/lib/python3.11/site-packages/flask/app.py:838]
Traceback (most recent call last):
  File "/Users/austinheywood/source/flask-auth-starter/venv/lib/python3.11/site-packages/flask/app.py", line 1473, in wsgi_app
    response = self.full_dispatch_request()
               ^^^^^^^^^^^^^^^^^^^^^^^^^^^^
  File "/Users/austinheywood/source/flask-auth-starter/venv/lib/python3.11/site-packages/flask/app.py", line 882, in full_dispatch_request
    rv = self.handle_user_exception(e)
         ^^^^^^^^^^^^^^^^^^^^^^^^^^^^^
  File "/Users/austinheywood/source/flask-auth-starter/venv/lib/python3.11/site-packages/flask/app.py", line 880, in full_dispatch_request
    rv = self.dispatch_request()
         ^^^^^^^^^^^^^^^^^^^^^^^
  File "/Users/austinheywood/source/flask-auth-starter/venv/lib/python3.11/site-packages/flask/app.py", line 865, in dispatch_request
    return self.ensure_sync(self.view_functions[rule.endpoint])(**view_args)  # type: ignore[no-any-return]
           ^^^^^^^^^^^^^^^^^^^^^^^^^^^^^^^^^^^^^^^^^^^^^^^^^^^^^^^^^^^^^^^^^
  File "/Users/austinheywood/source/flask-auth-starter/app/auth/routes.py", line 204, in forgot_password
    send_password_reset_email(user.email, reset_url)
  File "/Users/austinheywood/source/flask-auth-starter/app/email.py", line 23, in send_password_reset_email
    recipients = [user.email]
                  ^^^^^^^^^^
AttributeError: 'str' object has no attribute 'email'
2024-10-09 09:02:33,998 ERROR: Exception on /forgot-password [POST] [in /Users/austinheywood/source/flask-auth-starter/venv/lib/python3.11/site-packages/flask/app.py:838]
Traceback (most recent call last):
  File "/Users/austinheywood/source/flask-auth-starter/venv/lib/python3.11/site-packages/flask/app.py", line 1473, in wsgi_app
    response = self.full_dispatch_request()
               ^^^^^^^^^^^^^^^^^^^^^^^^^^^^
  File "/Users/austinheywood/source/flask-auth-starter/venv/lib/python3.11/site-packages/flask/app.py", line 882, in full_dispatch_request
    rv = self.handle_user_exception(e)
         ^^^^^^^^^^^^^^^^^^^^^^^^^^^^^
  File "/Users/austinheywood/source/flask-auth-starter/venv/lib/python3.11/site-packages/flask/app.py", line 880, in full_dispatch_request
    rv = self.dispatch_request()
         ^^^^^^^^^^^^^^^^^^^^^^^
  File "/Users/austinheywood/source/flask-auth-starter/venv/lib/python3.11/site-packages/flask/app.py", line 865, in dispatch_request
    return self.ensure_sync(self.view_functions[rule.endpoint])(**view_args)  # type: ignore[no-any-return]
           ^^^^^^^^^^^^^^^^^^^^^^^^^^^^^^^^^^^^^^^^^^^^^^^^^^^^^^^^^^^^^^^^^
  File "/Users/austinheywood/source/flask-auth-starter/app/auth/routes.py", line 204, in forgot_password
    send_password_reset_email(user, reset_url)
  File "/Users/austinheywood/source/flask-auth-starter/app/email.py", line 23, in send_password_reset_email
    recipients = [user.email]
                  ^^^^^^^^^^
AttributeError: 'str' object has no attribute 'email'
2024-10-09 09:06:57,214 INFO: Flask Auth Starter startup [in /Users/austinheywood/source/flask-auth-starter/app/__init__.py:60]
2024-10-09 09:09:41,830 DEBUG: User 1 org role: admin [in /Users/austinheywood/source/flask-auth-starter/app/auth/routes.py:25]
