2024-10-08 13:00:07,039 ERROR: Exception on /invite [POST] [in /Users/austinheywood/source/flask-auth-starter/venv/lib/python3.11/site-packages/flask/app.py:838]
Traceback (most recent call last):
  File "/Users/austinheywood/source/flask-auth-starter/venv/lib/python3.11/site-packages/flask/app.py", line 1473, in wsgi_app
    response = self.full_dispatch_request()
               ^^^^^^^^^^^^^^^^^^^^^^^^^^^^
  File "/Users/austinheywood/source/flask-auth-starter/venv/lib/python3.11/site-packages/flask/app.py", line 882, in full_dispatch_request
    rv = self.handle_user_exception(e)
         ^^^^^^^^^^^^^^^^^^^^^^^^^^^^^
  File "/Users/austinheywood/source/flask-auth-starter/venv/lib/python3.11/site-packages/flask/app.py", line 880, in full_dispatch_request
    rv = self.dispatch_request()
         ^^^^^^^^^^^^^^^^^^^^^^^
  File "/Users/austinheywood/source/flask-auth-starter/venv/lib/python3.11/site-packages/flask/app.py", line 865, in dispatch_request
    return self.ensure_sync(self.view_functions[rule.endpoint])(**view_args)  # type: ignore[no-any-return]
           ^^^^^^^^^^^^^^^^^^^^^^^^^^^^^^^^^^^^^^^^^^^^^^^^^^^^^^^^^^^^^^^^^
  File "/Users/austinheywood/source/flask-auth-starter/venv/lib/python3.11/site-packages/flask_login/utils.py", line 290, in decorated_view
    return current_app.ensure_sync(func)(*args, **kwargs)
           ^^^^^^^^^^^^^^^^^^^^^^^^^^^^^^^^^^^^^^^^^^^^^^
  File "/Users/austinheywood/source/flask-auth-starter/app/auth/routes.py", line 31, in decorated_function
    return f(*args, **kwargs)
           ^^^^^^^^^^^^^^^^^^
  File "/Users/austinheywood/source/flask-auth-starter/app/auth/routes.py", line 132, in invite_user
    send_invitation_email(email, current_user, g.current_organization, token)
  File "/Users/austinheywood/source/flask-auth-starter/app/email.py", line 27, in send_invitation_email
    sender=current_app.config['ADMINS'][0],
           ~~~~~~~~~~~~~~~~~~^^^^^^^^^^
KeyError: 'ADMINS'
2024-10-08 13:00:33,010 ERROR: Exception on /invite [POST] [in /Users/austinheywood/source/flask-auth-starter/venv/lib/python3.11/site-packages/flask/app.py:838]
Traceback (most recent call last):
  File "/Users/austinheywood/source/flask-auth-starter/venv/lib/python3.11/site-packages/flask/app.py", line 1473, in wsgi_app
    response = self.full_dispatch_request()
               ^^^^^^^^^^^^^^^^^^^^^^^^^^^^
  File "/Users/austinheywood/source/flask-auth-starter/venv/lib/python3.11/site-packages/flask/app.py", line 882, in full_dispatch_request
    rv = self.handle_user_exception(e)
         ^^^^^^^^^^^^^^^^^^^^^^^^^^^^^
  File "/Users/austinheywood/source/flask-auth-starter/venv/lib/python3.11/site-packages/flask/app.py", line 880, in full_dispatch_request
    rv = self.dispatch_request()
         ^^^^^^^^^^^^^^^^^^^^^^^
  File "/Users/austinheywood/source/flask-auth-starter/venv/lib/python3.11/site-packages/flask/app.py", line 865, in dispatch_request
    return self.ensure_sync(self.view_functions[rule.endpoint])(**view_args)  # type: ignore[no-any-return]
           ^^^^^^^^^^^^^^^^^^^^^^^^^^^^^^^^^^^^^^^^^^^^^^^^^^^^^^^^^^^^^^^^^
  File "/Users/austinheywood/source/flask-auth-starter/venv/lib/python3.11/site-packages/flask_login/utils.py", line 290, in decorated_view
    return current_app.ensure_sync(func)(*args, **kwargs)
           ^^^^^^^^^^^^^^^^^^^^^^^^^^^^^^^^^^^^^^^^^^^^^^
  File "/Users/austinheywood/source/flask-auth-starter/app/auth/routes.py", line 31, in decorated_function
    return f(*args, **kwargs)
           ^^^^^^^^^^^^^^^^^^
  File "/Users/austinheywood/source/flask-auth-starter/app/auth/routes.py", line 132, in invite_user
    send_invitation_email(email, current_user, g.current_organization, token)
  File "/Users/austinheywood/source/flask-auth-starter/app/email.py", line 27, in send_invitation_email
    sender=current_app.config['ADMINS'][0],
           ~~~~~~~~~~~~~~~~~~^^^^^^^^^^
KeyError: 'ADMINS'
2024-10-08 13:03:07,906 INFO: Flask Auth Starter [in /Users/austinheywood/source/flask-auth-starter/app/__init__.py:49]
2024-10-08 13:03:07,907 INFO: Flask Auth Starter startup [in /Users/austinheywood/source/flask-auth-starter/app/__init__.py:60]
2024-10-08 13:04:13,441 INFO: Flask Auth Starter [in /Users/austinheywood/source/flask-auth-starter/app/__init__.py:49]
2024-10-08 13:04:13,441 INFO: Flask Auth Starter startup [in /Users/austinheywood/source/flask-auth-starter/app/__init__.py:60]
2024-10-08 13:04:19,474 ERROR: Exception on /invite [POST] [in /Users/austinheywood/source/flask-auth-starter/venv/lib/python3.11/site-packages/flask/app.py:838]
Traceback (most recent call last):
  File "/Users/austinheywood/source/flask-auth-starter/venv/lib/python3.11/site-packages/flask/app.py", line 1473, in wsgi_app
    response = self.full_dispatch_request()
               ^^^^^^^^^^^^^^^^^^^^^^^^^^^^
  File "/Users/austinheywood/source/flask-auth-starter/venv/lib/python3.11/site-packages/flask/app.py", line 882, in full_dispatch_request
    rv = self.handle_user_exception(e)
         ^^^^^^^^^^^^^^^^^^^^^^^^^^^^^
  File "/Users/austinheywood/source/flask-auth-starter/venv/lib/python3.11/site-packages/flask/app.py", line 880, in full_dispatch_request
    rv = self.dispatch_request()
         ^^^^^^^^^^^^^^^^^^^^^^^
  File "/Users/austinheywood/source/flask-auth-starter/venv/lib/python3.11/site-packages/flask/app.py", line 865, in dispatch_request
    return self.ensure_sync(self.view_functions[rule.endpoint])(**view_args)  # type: ignore[no-any-return]
           ^^^^^^^^^^^^^^^^^^^^^^^^^^^^^^^^^^^^^^^^^^^^^^^^^^^^^^^^^^^^^^^^^
  File "/Users/austinheywood/source/flask-auth-starter/venv/lib/python3.11/site-packages/flask_login/utils.py", line 290, in decorated_view
    return current_app.ensure_sync(func)(*args, **kwargs)
           ^^^^^^^^^^^^^^^^^^^^^^^^^^^^^^^^^^^^^^^^^^^^^^
  File "/Users/austinheywood/source/flask-auth-starter/app/auth/routes.py", line 31, in decorated_function
    return f(*args, **kwargs)
           ^^^^^^^^^^^^^^^^^^
  File "/Users/austinheywood/source/flask-auth-starter/app/auth/routes.py", line 132, in invite_user
    send_invitation_email(email, current_user, g.current_organization, token)
  File "/Users/austinheywood/source/flask-auth-starter/app/email.py", line 26, in send_invitation_email
    send_email(f'Invite to Join {organization.name}',
TypeError: send_email() missing 1 required positional argument: 'html_body'
2024-10-08 13:06:35,420 INFO: Flask Auth Starter [in /Users/austinheywood/source/flask-auth-starter/app/__init__.py:49]
2024-10-08 13:06:35,420 INFO: Flask Auth Starter startup [in /Users/austinheywood/source/flask-auth-starter/app/__init__.py:60]
2024-10-08 13:06:38,829 ERROR: Exception on /invite [POST] [in /Users/austinheywood/source/flask-auth-starter/venv/lib/python3.11/site-packages/flask/app.py:838]
Traceback (most recent call last):
  File "/Users/austinheywood/source/flask-auth-starter/venv/lib/python3.11/site-packages/flask/app.py", line 1473, in wsgi_app
    response = self.full_dispatch_request()
               ^^^^^^^^^^^^^^^^^^^^^^^^^^^^
  File "/Users/austinheywood/source/flask-auth-starter/venv/lib/python3.11/site-packages/flask/app.py", line 882, in full_dispatch_request
    rv = self.handle_user_exception(e)
         ^^^^^^^^^^^^^^^^^^^^^^^^^^^^^
  File "/Users/austinheywood/source/flask-auth-starter/venv/lib/python3.11/site-packages/flask/app.py", line 880, in full_dispatch_request
    rv = self.dispatch_request()
         ^^^^^^^^^^^^^^^^^^^^^^^
  File "/Users/austinheywood/source/flask-auth-starter/venv/lib/python3.11/site-packages/flask/app.py", line 865, in dispatch_request
    return self.ensure_sync(self.view_functions[rule.endpoint])(**view_args)  # type: ignore[no-any-return]
           ^^^^^^^^^^^^^^^^^^^^^^^^^^^^^^^^^^^^^^^^^^^^^^^^^^^^^^^^^^^^^^^^^
  File "/Users/austinheywood/source/flask-auth-starter/venv/lib/python3.11/site-packages/flask_login/utils.py", line 290, in decorated_view
    return current_app.ensure_sync(func)(*args, **kwargs)
           ^^^^^^^^^^^^^^^^^^^^^^^^^^^^^^^^^^^^^^^^^^^^^^
  File "/Users/austinheywood/source/flask-auth-starter/app/auth/routes.py", line 31, in decorated_function
    return f(*args, **kwargs)
           ^^^^^^^^^^^^^^^^^^
  File "/Users/austinheywood/source/flask-auth-starter/app/auth/routes.py", line 132, in invite_user
    send_invitation_email(email, current_user, g.current_organization, token)
  File "/Users/austinheywood/source/flask-auth-starter/app/email.py", line 25, in send_invitation_email
    send_email(f'Invite to Join {organization.name}',
TypeError: send_email() missing 1 required positional argument: 'html_body'
2024-10-08 13:07:11,893 INFO: Flask Auth Starter [in /Users/austinheywood/source/flask-auth-starter/app/__init__.py:49]
2024-10-08 13:07:11,894 INFO: Flask Auth Starter startup [in /Users/austinheywood/source/flask-auth-starter/app/__init__.py:60]
2024-10-08 13:09:18,316 INFO: Flask Auth Starter [in /Users/austinheywood/source/flask-auth-starter/app/__init__.py:49]
2024-10-08 13:09:18,316 INFO: Flask Auth Starter startup [in /Users/austinheywood/source/flask-auth-starter/app/__init__.py:60]
2024-10-08 13:10:35,398 INFO: Flask Auth Starter [in /Users/austinheywood/source/flask-auth-starter/app/__init__.py:49]
2024-10-08 13:10:35,399 INFO: Flask Auth Starter startup [in /Users/austinheywood/source/flask-auth-starter/app/__init__.py:60]
2024-10-08 13:13:21,637 INFO: Flask Auth Starter [in /Users/austinheywood/source/flask-auth-starter/app/__init__.py:49]
2024-10-08 13:13:21,638 INFO: Flask Auth Starter startup [in /Users/austinheywood/source/flask-auth-starter/app/__init__.py:60]
2024-10-08 13:15:52,343 INFO: Flask Auth Starter [in /Users/austinheywood/source/flask-auth-starter/app/__init__.py:49]
2024-10-08 13:15:52,343 INFO: Flask Auth Starter startup [in /Users/austinheywood/source/flask-auth-starter/app/__init__.py:60]
2024-10-08 13:18:11,660 INFO: Flask Auth Starter [in /Users/austinheywood/source/flask-auth-starter/app/__init__.py:49]
2024-10-08 13:18:11,660 INFO: Flask Auth Starter startup [in /Users/austinheywood/source/flask-auth-starter/app/__init__.py:60]
