2024-10-08 13:20:52,449 INFO: Flask Auth Starter [in /Users/austinheywood/source/flask-auth-starter/app/__init__.py:49]
2024-10-08 13:20:52,449 INFO: Flask Auth Starter startup [in /Users/austinheywood/source/flask-auth-starter/app/__init__.py:60]
2024-10-08 13:25:34,327 INFO: Flask Auth Starter [in /Users/austinheywood/source/flask-auth-starter/app/__init__.py:49]
2024-10-08 13:25:34,327 INFO: Flask Auth Starter startup [in /Users/austinheywood/source/flask-auth-starter/app/__init__.py:60]
2024-10-08 13:30:50,001 INFO: Flask Auth Starter [in /Users/austinheywood/source/flask-auth-starter/app/__init__.py:49]
2024-10-08 13:30:50,001 INFO: Flask Auth Starter startup [in /Users/austinheywood/source/flask-auth-starter/app/__init__.py:60]
2024-10-08 13:31:03,861 INFO: Flask Auth Starter [in /Users/austinheywood/source/flask-auth-starter/app/__init__.py:49]
2024-10-08 13:31:03,861 INFO: Flask Auth Starter startup [in /Users/austinheywood/source/flask-auth-starter/app/__init__.py:60]
2024-10-08 13:33:11,187 INFO: Flask Auth Starter [in /Users/austinheywood/source/flask-auth-starter/app/__init__.py:49]
2024-10-08 13:33:11,187 INFO: Flask Auth Starter startup [in /Users/austinheywood/source/flask-auth-starter/app/__init__.py:60]
2024-10-08 13:33:14,269 ERROR: Exception on /invite [POST] [in /Users/austinheywood/source/flask-auth-starter/venv/lib/python3.11/site-packages/flask/app.py:838]
Traceback (most recent call last):
  File "/Users/austinheywood/source/flask-auth-starter/venv/lib/python3.11/site-packages/flask/app.py", line 1473, in wsgi_app
    response = self.full_dispatch_request()
               ^^^^^^^^^^^^^^^^^^^^^^^^^^^^
  File "/Users/austinheywood/source/flask-auth-starter/venv/lib/python3.11/site-packages/flask/app.py", line 882, in full_dispatch_request
    rv = self.handle_user_exception(e)
         ^^^^^^^^^^^^^^^^^^^^^^^^^^^^^
  File "/Users/austinheywood/source/flask-auth-starter/venv/lib/python3.11/site-packages/flask/app.py", line 880, in full_dispatch_request
    rv = self.dispatch_request()
         ^^^^^^^^^^^^^^^^^^^^^^^
  File "/Users/austinheywood/source/flask-auth-starter/venv/lib/python3.11/site-packages/flask/app.py", line 865, in dispatch_request
    return self.ensure_sync(self.view_functions[rule.endpoint])(**view_args)  # type: ignore[no-any-return]
           ^^^^^^^^^^^^^^^^^^^^^^^^^^^^^^^^^^^^^^^^^^^^^^^^^^^^^^^^^^^^^^^^^
  File "/Users/austinheywood/source/flask-auth-starter/venv/lib/python3.11/site-packages/flask_login/utils.py", line 290, in decorated_view
    return current_app.ensure_sync(func)(*args, **kwargs)
           ^^^^^^^^^^^^^^^^^^^^^^^^^^^^^^^^^^^^^^^^^^^^^^
  File "/Users/austinheywood/source/flask-auth-starter/app/auth/routes.py", line 31, in decorated_function
    return f(*args, **kwargs)
           ^^^^^^^^^^^^^^^^^^
  File "/Users/austinheywood/source/flask-auth-starter/app/auth/routes.py", line 132, in invite_user
    send_invitation_email(email, current_user, g.current_organization, token)
  File "/Users/austinheywood/source/flask-auth-starter/app/email.py", line 36, in send_invitation_email
    text_body = render_template(template_path,
                ^^^^^^^^^^^^^^^^^^^^^^^^^^^^^^
  File "/Users/austinheywood/source/flask-auth-starter/venv/lib/python3.11/site-packages/flask/templating.py", line 149, in render_template
    template = app.jinja_env.get_or_select_template(template_name_or_list)
               ^^^^^^^^^^^^^^^^^^^^^^^^^^^^^^^^^^^^^^^^^^^^^^^^^^^^^^^^^^^
  File "/Users/austinheywood/source/flask-auth-starter/venv/lib/python3.11/site-packages/jinja2/environment.py", line 1084, in get_or_select_template
    return self.get_template(template_name_or_list, parent, globals)
           ^^^^^^^^^^^^^^^^^^^^^^^^^^^^^^^^^^^^^^^^^^^^^^^^^^^^^^^^^
  File "/Users/austinheywood/source/flask-auth-starter/venv/lib/python3.11/site-packages/jinja2/environment.py", line 1013, in get_template
    return self._load_template(name, globals)
           ^^^^^^^^^^^^^^^^^^^^^^^^^^^^^^^^^^
  File "/Users/austinheywood/source/flask-auth-starter/venv/lib/python3.11/site-packages/jinja2/environment.py", line 972, in _load_template
    template = self.loader.load(self, name, self.make_globals(globals))
               ^^^^^^^^^^^^^^^^^^^^^^^^^^^^^^^^^^^^^^^^^^^^^^^^^^^^^^^^
  File "/Users/austinheywood/source/flask-auth-starter/venv/lib/python3.11/site-packages/jinja2/loaders.py", line 126, in load
    source, filename, uptodate = self.get_source(environment, name)
                                 ^^^^^^^^^^^^^^^^^^^^^^^^^^^^^^^^^^
  File "/Users/austinheywood/source/flask-auth-starter/venv/lib/python3.11/site-packages/flask/templating.py", line 65, in get_source
    return self._get_source_fast(environment, template)
           ^^^^^^^^^^^^^^^^^^^^^^^^^^^^^^^^^^^^^^^^^^^^
  File "/Users/austinheywood/source/flask-auth-starter/venv/lib/python3.11/site-packages/flask/templating.py", line 99, in _get_source_fast
    raise TemplateNotFound(template)
jinja2.exceptions.TemplateNotFound: templates/email/org_invite.txt
2024-10-08 13:34:12,062 INFO: Flask Auth Starter [in /Users/austinheywood/source/flask-auth-starter/app/__init__.py:49]
2024-10-08 13:34:12,062 INFO: Flask Auth Starter startup [in /Users/austinheywood/source/flask-auth-starter/app/__init__.py:60]
2024-10-08 13:34:14,026 ERROR: Exception on /invite [POST] [in /Users/austinheywood/source/flask-auth-starter/venv/lib/python3.11/site-packages/flask/app.py:838]
Traceback (most recent call last):
  File "/Users/austinheywood/source/flask-auth-starter/venv/lib/python3.11/site-packages/flask/app.py", line 1473, in wsgi_app
    response = self.full_dispatch_request()
               ^^^^^^^^^^^^^^^^^^^^^^^^^^^^
  File "/Users/austinheywood/source/flask-auth-starter/venv/lib/python3.11/site-packages/flask/app.py", line 882, in full_dispatch_request
    rv = self.handle_user_exception(e)
         ^^^^^^^^^^^^^^^^^^^^^^^^^^^^^
  File "/Users/austinheywood/source/flask-auth-starter/venv/lib/python3.11/site-packages/flask/app.py", line 880, in full_dispatch_request
    rv = self.dispatch_request()
         ^^^^^^^^^^^^^^^^^^^^^^^
  File "/Users/austinheywood/source/flask-auth-starter/venv/lib/python3.11/site-packages/flask/app.py", line 865, in dispatch_request
    return self.ensure_sync(self.view_functions[rule.endpoint])(**view_args)  # type: ignore[no-any-return]
           ^^^^^^^^^^^^^^^^^^^^^^^^^^^^^^^^^^^^^^^^^^^^^^^^^^^^^^^^^^^^^^^^^
  File "/Users/austinheywood/source/flask-auth-starter/venv/lib/python3.11/site-packages/flask_login/utils.py", line 290, in decorated_view
    return current_app.ensure_sync(func)(*args, **kwargs)
           ^^^^^^^^^^^^^^^^^^^^^^^^^^^^^^^^^^^^^^^^^^^^^^
  File "/Users/austinheywood/source/flask-auth-starter/app/auth/routes.py", line 31, in decorated_function
    return f(*args, **kwargs)
           ^^^^^^^^^^^^^^^^^^
  File "/Users/austinheywood/source/flask-auth-starter/app/auth/routes.py", line 132, in invite_user
    send_invitation_email(email, current_user, g.current_organization, token)
  File "/Users/austinheywood/source/flask-auth-starter/app/email.py", line 36, in send_invitation_email
    text_body = render_template(template_path,
                ^^^^^^^^^^^^^^^^^^^^^^^^^^^^^^
  File "/Users/austinheywood/source/flask-auth-starter/venv/lib/python3.11/site-packages/flask/templating.py", line 150, in render_template
    return _render(app, template, context)
           ^^^^^^^^^^^^^^^^^^^^^^^^^^^^^^^
  File "/Users/austinheywood/source/flask-auth-starter/venv/lib/python3.11/site-packages/flask/templating.py", line 131, in _render
    rv = template.render(context)
         ^^^^^^^^^^^^^^^^^^^^^^^^
  File "/Users/austinheywood/source/flask-auth-starter/venv/lib/python3.11/site-packages/jinja2/environment.py", line 1304, in render
    self.environment.handle_exception()
  File "/Users/austinheywood/source/flask-auth-starter/venv/lib/python3.11/site-packages/jinja2/environment.py", line 939, in handle_exception
    raise rewrite_traceback_stack(source=source)
  File "/Users/austinheywood/source/flask-auth-starter/app/templates/email/org_invite.txt", line 7, in top-level template code
    {{ url_for('auth.accept_invitation', token=token, _external=True) }}
    ^^^^^^^^^^^^^^^^^^^^^^^^^
  File "/Users/austinheywood/source/flask-auth-starter/venv/lib/python3.11/site-packages/flask/app.py", line 1084, in url_for
    return self.handle_url_build_error(error, endpoint, values)
           ^^^^^^^^^^^^^^^^^^^^^^^^^^^^^^^^^^^^^^^^^^^^^^^^^^^^
  File "/Users/austinheywood/source/flask-auth-starter/venv/lib/python3.11/site-packages/flask/app.py", line 1073, in url_for
    rv = url_adapter.build(  # type: ignore[union-attr]
         ^^^^^^^^^^^^^^^^^^^^^^^^^^^^^^^^^^^^^^^^^^^^^^
  File "/Users/austinheywood/source/flask-auth-starter/venv/lib/python3.11/site-packages/werkzeug/routing/map.py", line 924, in build
    raise BuildError(endpoint, values, method, self)
werkzeug.routing.exceptions.BuildError: Could not build url for endpoint 'auth.accept_invitation' with values ['token']. Did you mean 'auth.create_organization' instead?
2024-10-08 13:34:37,262 INFO: Flask Auth Starter [in /Users/austinheywood/source/flask-auth-starter/app/__init__.py:49]
2024-10-08 13:34:37,262 INFO: Flask Auth Starter startup [in /Users/austinheywood/source/flask-auth-starter/app/__init__.py:60]
