2024-10-08 13:56:47,160 ERROR: Exception on /invite [POST] [in /Users/austinheywood/source/flask-auth-starter/venv/lib/python3.11/site-packages/flask/app.py:838]
Traceback (most recent call last):
  File "/Users/austinheywood/source/flask-auth-starter/venv/lib/python3.11/site-packages/flask/app.py", line 1473, in wsgi_app
    response = self.full_dispatch_request()
               ^^^^^^^^^^^^^^^^^^^^^^^^^^^^
  File "/Users/austinheywood/source/flask-auth-starter/venv/lib/python3.11/site-packages/flask/app.py", line 882, in full_dispatch_request
    rv = self.handle_user_exception(e)
         ^^^^^^^^^^^^^^^^^^^^^^^^^^^^^
  File "/Users/austinheywood/source/flask-auth-starter/venv/lib/python3.11/site-packages/flask/app.py", line 880, in full_dispatch_request
    rv = self.dispatch_request()
         ^^^^^^^^^^^^^^^^^^^^^^^
  File "/Users/austinheywood/source/flask-auth-starter/venv/lib/python3.11/site-packages/flask/app.py", line 865, in dispatch_request
    return self.ensure_sync(self.view_functions[rule.endpoint])(**view_args)  # type: ignore[no-any-return]
           ^^^^^^^^^^^^^^^^^^^^^^^^^^^^^^^^^^^^^^^^^^^^^^^^^^^^^^^^^^^^^^^^^
  File "/Users/austinheywood/source/flask-auth-starter/venv/lib/python3.11/site-packages/flask_login/utils.py", line 290, in decorated_view
    return current_app.ensure_sync(func)(*args, **kwargs)
           ^^^^^^^^^^^^^^^^^^^^^^^^^^^^^^^^^^^^^^^^^^^^^^
  File "/Users/austinheywood/source/flask-auth-starter/app/auth/routes.py", line 29, in decorated_function
    return f(*args, **kwargs)
           ^^^^^^^^^^^^^^^^^^
  File "/Users/austinheywood/source/flask-auth-starter/app/auth/routes.py", line 144, in invite_user
    send_invitation_email(email, current_user, g.current_organization)
  File "/Users/austinheywood/source/flask-auth-starter/app/email.py", line 39, in send_invitation_email
    user=User.query.filter_by(email=email).first(),
         ^^^^
NameError: name 'User' is not defined
2024-10-08 13:57:19,476 INFO: Flask Auth Starter [in /Users/austinheywood/source/flask-auth-starter/app/__init__.py:49]
2024-10-08 13:57:19,476 INFO: Flask Auth Starter startup [in /Users/austinheywood/source/flask-auth-starter/app/__init__.py:60]
