2024-10-08 13:56:47,160 ERROR: Exception on /invite [POST] [in /Users/austinheywood/source/flask-auth-starter/venv/lib/python3.11/site-packages/flask/app.py:838]
Traceback (most recent call last):
  File "/Users/austinheywood/source/flask-auth-starter/venv/lib/python3.11/site-packages/flask/app.py", line 1473, in wsgi_app
    response = self.full_dispatch_request()
               ^^^^^^^^^^^^^^^^^^^^^^^^^^^^
  File "/Users/austinheywood/source/flask-auth-starter/venv/lib/python3.11/site-packages/flask/app.py", line 882, in full_dispatch_request
    rv = self.handle_user_exception(e)
         ^^^^^^^^^^^^^^^^^^^^^^^^^^^^^
  File "/Users/austinheywood/source/flask-auth-starter/venv/lib/python3.11/site-packages/flask/app.py", line 880, in full_dispatch_request
    rv = self.dispatch_request()
         ^^^^^^^^^^^^^^^^^^^^^^^
  File "/Users/austinheywood/source/flask-auth-starter/venv/lib/python3.11/site-packages/flask/app.py", line 865, in dispatch_request
    return self.ensure_sync(self.view_functions[rule.endpoint])(**view_args)  # type: ignore[no-any-return]
           ^^^^^^^^^^^^^^^^^^^^^^^^^^^^^^^^^^^^^^^^^^^^^^^^^^^^^^^^^^^^^^^^^
  File "/Users/austinheywood/source/flask-auth-starter/venv/lib/python3.11/site-packages/flask_login/utils.py", line 290, in decorated_view
    return current_app.ensure_sync(func)(*args, **kwargs)
           ^^^^^^^^^^^^^^^^^^^^^^^^^^^^^^^^^^^^^^^^^^^^^^
  File "/Users/austinheywood/source/flask-auth-starter/app/auth/routes.py", line 29, in decorated_function
    return f(*args, **kwargs)
           ^^^^^^^^^^^^^^^^^^
  File "/Users/austinheywood/source/flask-auth-starter/app/auth/routes.py", line 144, in invite_user
    send_invitation_email(email, current_user, g.current_organization)
  File "/Users/austinheywood/source/flask-auth-starter/app/email.py", line 39, in send_invitation_email
    user=User.query.filter_by(email=email).first(),
         ^^^^
NameError: name 'User' is not defined
2024-10-08 13:57:19,476 INFO: Flask Auth Starter [in /Users/austinheywood/source/flask-auth-starter/app/__init__.py:49]
2024-10-08 13:57:19,476 INFO: Flask Auth Starter startup [in /Users/austinheywood/source/flask-auth-starter/app/__init__.py:60]
2024-10-09 00:02:07,282 INFO: Flask Auth Starter [in /Users/austinheywood/source/flask-auth-starter/app/__init__.py:49]
2024-10-09 00:02:07,282 INFO: Flask Auth Starter startup [in /Users/austinheywood/source/flask-auth-starter/app/__init__.py:60]
2024-10-09 00:02:14,012 INFO: Flask Auth Starter [in /Users/austinheywood/source/flask-auth-starter/app/__init__.py:49]
2024-10-09 00:02:14,012 INFO: Flask Auth Starter startup [in /Users/austinheywood/source/flask-auth-starter/app/__init__.py:60]
2024-10-09 00:03:09,957 INFO: Flask Auth Starter [in /Users/austinheywood/source/flask-auth-starter/app/__init__.py:49]
2024-10-09 00:03:09,958 INFO: Flask Auth Starter startup [in /Users/austinheywood/source/flask-auth-starter/app/__init__.py:60]
2024-10-09 00:03:16,130 INFO: Flask Auth Starter [in /Users/austinheywood/source/flask-auth-starter/app/__init__.py:49]
2024-10-09 00:03:16,130 INFO: Flask Auth Starter startup [in /Users/austinheywood/source/flask-auth-starter/app/__init__.py:60]
2024-10-09 00:08:26,395 INFO: Flask Auth Starter [in /Users/austinheywood/source/flask-auth-starter/app/__init__.py:49]
2024-10-09 00:08:26,395 INFO: Flask Auth Starter startup [in /Users/austinheywood/source/flask-auth-starter/app/__init__.py:60]
2024-10-09 00:13:48,433 INFO: Flask Auth Starter [in /Users/austinheywood/source/flask-auth-starter/app/__init__.py:49]
2024-10-09 00:13:48,433 INFO: Flask Auth Starter startup [in /Users/austinheywood/source/flask-auth-starter/app/__init__.py:60]
2024-10-09 00:16:57,916 INFO: Flask Auth Starter [in /Users/austinheywood/source/flask-auth-starter/app/__init__.py:49]
2024-10-09 00:16:57,916 INFO: Flask Auth Starter startup [in /Users/austinheywood/source/flask-auth-starter/app/__init__.py:60]
2024-10-09 00:19:09,633 INFO: Flask Auth Starter [in /Users/austinheywood/source/flask-auth-starter/app/__init__.py:49]
2024-10-09 00:19:09,633 INFO: Flask Auth Starter startup [in /Users/austinheywood/source/flask-auth-starter/app/__init__.py:60]
2024-10-09 00:19:12,922 ERROR: Exception on /org/members [GET] [in /Users/austinheywood/source/flask-auth-starter/venv/lib/python3.11/site-packages/flask/app.py:838]
Traceback (most recent call last):
  File "/Users/austinheywood/source/flask-auth-starter/venv/lib/python3.11/site-packages/flask/app.py", line 1473, in wsgi_app
    response = self.full_dispatch_request()
               ^^^^^^^^^^^^^^^^^^^^^^^^^^^^
  File "/Users/austinheywood/source/flask-auth-starter/venv/lib/python3.11/site-packages/flask/app.py", line 882, in full_dispatch_request
    rv = self.handle_user_exception(e)
         ^^^^^^^^^^^^^^^^^^^^^^^^^^^^^
  File "/Users/austinheywood/source/flask-auth-starter/venv/lib/python3.11/site-packages/flask/app.py", line 880, in full_dispatch_request
    rv = self.dispatch_request()
         ^^^^^^^^^^^^^^^^^^^^^^^
  File "/Users/austinheywood/source/flask-auth-starter/venv/lib/python3.11/site-packages/flask/app.py", line 865, in dispatch_request
    return self.ensure_sync(self.view_functions[rule.endpoint])(**view_args)  # type: ignore[no-any-return]
           ^^^^^^^^^^^^^^^^^^^^^^^^^^^^^^^^^^^^^^^^^^^^^^^^^^^^^^^^^^^^^^^^^
  File "/Users/austinheywood/source/flask-auth-starter/venv/lib/python3.11/site-packages/flask_login/utils.py", line 290, in decorated_view
    return current_app.ensure_sync(func)(*args, **kwargs)
           ^^^^^^^^^^^^^^^^^^^^^^^^^^^^^^^^^^^^^^^^^^^^^^
  File "/Users/austinheywood/source/flask-auth-starter/app/auth/routes.py", line 30, in decorated_function
    return f(*args, **kwargs)
           ^^^^^^^^^^^^^^^^^^
  File "/Users/austinheywood/source/flask-auth-starter/app/org/routes.py", line 21, in members
    return render_template('org/members.html', members=members, invitations=invitations)
           ^^^^^^^^^^^^^^^^^^^^^^^^^^^^^^^^^^^^^^^^^^^^^^^^^^^^^^^^^^^^^^^^^^^^^^^^^^^^^
  File "/Users/austinheywood/source/flask-auth-starter/venv/lib/python3.11/site-packages/flask/templating.py", line 150, in render_template
    return _render(app, template, context)
           ^^^^^^^^^^^^^^^^^^^^^^^^^^^^^^^
  File "/Users/austinheywood/source/flask-auth-starter/venv/lib/python3.11/site-packages/flask/templating.py", line 131, in _render
    rv = template.render(context)
         ^^^^^^^^^^^^^^^^^^^^^^^^
  File "/Users/austinheywood/source/flask-auth-starter/venv/lib/python3.11/site-packages/jinja2/environment.py", line 1304, in render
    self.environment.handle_exception()
  File "/Users/austinheywood/source/flask-auth-starter/venv/lib/python3.11/site-packages/jinja2/environment.py", line 939, in handle_exception
    raise rewrite_traceback_stack(source=source)
  File "/Users/austinheywood/source/flask-auth-starter/app/templates/org/members.html", line 1, in top-level template code
    {% extends "base.html" %}
  File "/Users/austinheywood/source/flask-auth-starter/app/templates/base.html", line 39, in top-level template code
    {% block content %}{% endblock %}
    ^^^^^^^^^^^^^^^^^^^^^^^^^
  File "/Users/austinheywood/source/flask-auth-starter/app/templates/org/members.html", line 52, in block 'content'
    <form method="post" action="{{ url_for('org.revoke_invitation', invitation_id=invitation.id) }}">
    ^^^^^^^^^^^^^^^^^^^^^^^^^
  File "/Users/austinheywood/source/flask-auth-starter/venv/lib/python3.11/site-packages/flask/app.py", line 1084, in url_for
    return self.handle_url_build_error(error, endpoint, values)
           ^^^^^^^^^^^^^^^^^^^^^^^^^^^^^^^^^^^^^^^^^^^^^^^^^^^^
  File "/Users/austinheywood/source/flask-auth-starter/venv/lib/python3.11/site-packages/flask/app.py", line 1073, in url_for
    rv = url_adapter.build(  # type: ignore[union-attr]
         ^^^^^^^^^^^^^^^^^^^^^^^^^^^^^^^^^^^^^^^^^^^^^^
  File "/Users/austinheywood/source/flask-auth-starter/venv/lib/python3.11/site-packages/werkzeug/routing/map.py", line 924, in build
    raise BuildError(endpoint, values, method, self)
werkzeug.routing.exceptions.BuildError: Could not build url for endpoint 'org.revoke_invitation' with values ['invitation_id']. Did you mean 'auth.accept_invitation' instead?
2024-10-09 00:20:29,137 INFO: Flask Auth Starter [in /Users/austinheywood/source/flask-auth-starter/app/__init__.py:49]
2024-10-09 00:20:29,138 INFO: Flask Auth Starter startup [in /Users/austinheywood/source/flask-auth-starter/app/__init__.py:60]
2024-10-09 08:51:16,737 INFO: Flask Auth Starter [in /Users/austinheywood/source/flask-auth-starter/app/__init__.py:49]
2024-10-09 08:51:16,738 INFO: Flask Auth Starter startup [in /Users/austinheywood/source/flask-auth-starter/app/__init__.py:60]
2024-10-09 08:51:22,568 INFO: Flask Auth Starter [in /Users/austinheywood/source/flask-auth-starter/app/__init__.py:49]
2024-10-09 08:51:22,568 INFO: Flask Auth Starter startup [in /Users/austinheywood/source/flask-auth-starter/app/__init__.py:60]
2024-10-09 08:52:14,408 INFO: Flask Auth Starter [in /Users/austinheywood/source/flask-auth-starter/app/__init__.py:49]
2024-10-09 08:52:14,408 INFO: Flask Auth Starter startup [in /Users/austinheywood/source/flask-auth-starter/app/__init__.py:60]
2024-10-09 08:52:21,404 INFO: Flask Auth Starter [in /Users/austinheywood/source/flask-auth-starter/app/__init__.py:49]
2024-10-09 08:52:21,404 INFO: Flask Auth Starter startup [in /Users/austinheywood/source/flask-auth-starter/app/__init__.py:60]
2024-10-09 08:54:15,578 INFO: Flask Auth Starter [in /Users/austinheywood/source/flask-auth-starter/app/__init__.py:49]
2024-10-09 08:54:15,578 INFO: Flask Auth Starter startup [in /Users/austinheywood/source/flask-auth-starter/app/__init__.py:60]
