2024-10-01 10:45:02,141 ERROR: Exception on /login [GET] [in /Users/austinheywood/source/api/venv/lib/python3.11/site-packages/flask/app.py:838]
Traceback (most recent call last):
  File "/Users/austinheywood/source/api/venv/lib/python3.11/site-packages/flask/app.py", line 1473, in wsgi_app
    response = self.full_dispatch_request()
               ^^^^^^^^^^^^^^^^^^^^^^^^^^^^
  File "/Users/austinheywood/source/api/venv/lib/python3.11/site-packages/flask/app.py", line 882, in full_dispatch_request
    rv = self.handle_user_exception(e)
         ^^^^^^^^^^^^^^^^^^^^^^^^^^^^^
  File "/Users/austinheywood/source/api/venv/lib/python3.11/site-packages/flask/app.py", line 880, in full_dispatch_request
    rv = self.dispatch_request()
         ^^^^^^^^^^^^^^^^^^^^^^^
  File "/Users/austinheywood/source/api/venv/lib/python3.11/site-packages/flask/app.py", line 865, in dispatch_request
    return self.ensure_sync(self.view_functions[rule.endpoint])(**view_args)  # type: ignore[no-any-return]
           ^^^^^^^^^^^^^^^^^^^^^^^^^^^^^^^^^^^^^^^^^^^^^^^^^^^^^^^^^^^^^^^^^
  File "/Users/austinheywood/source/api/app/auth/routes.py", line 25, in login
    return render_template('auth/login.html', title='Sign In')
           ^^^^^^^^^^^^^^^^^^^^^^^^^^^^^^^^^^^^^^^^^^^^^^^^^^^
  File "/Users/austinheywood/source/api/venv/lib/python3.11/site-packages/flask/templating.py", line 150, in render_template
    return _render(app, template, context)
           ^^^^^^^^^^^^^^^^^^^^^^^^^^^^^^^
  File "/Users/austinheywood/source/api/venv/lib/python3.11/site-packages/flask/templating.py", line 131, in _render
    rv = template.render(context)
         ^^^^^^^^^^^^^^^^^^^^^^^^
  File "/Users/austinheywood/source/api/venv/lib/python3.11/site-packages/jinja2/environment.py", line 1304, in render
    self.environment.handle_exception()
  File "/Users/austinheywood/source/api/venv/lib/python3.11/site-packages/jinja2/environment.py", line 939, in handle_exception
    raise rewrite_traceback_stack(source=source)
  File "/Users/austinheywood/source/api/app/templates/auth/login.html", line 1, in top-level template code
    {% extends "base.html" %}
  File "/Users/austinheywood/source/api/app/templates/base.html", line 41, in top-level template code
    {% block content %}{% endblock %}
    ^^^^^^^^^^^^^^^^^^^^^^^^^
  File "/Users/austinheywood/source/api/app/templates/auth/login.html", line 17, in block 'content'
    <p>New User? <a href="{{ url_for('signup') }}">Click to Sign Up!</a></p>
    ^^^^^^^^^^^^^^^^^^^^^^^^^
  File "/Users/austinheywood/source/api/venv/lib/python3.11/site-packages/flask/app.py", line 1084, in url_for
    return self.handle_url_build_error(error, endpoint, values)
           ^^^^^^^^^^^^^^^^^^^^^^^^^^^^^^^^^^^^^^^^^^^^^^^^^^^^
  File "/Users/austinheywood/source/api/venv/lib/python3.11/site-packages/flask/app.py", line 1073, in url_for
    rv = url_adapter.build(  # type: ignore[union-attr]
         ^^^^^^^^^^^^^^^^^^^^^^^^^^^^^^^^^^^^^^^^^^^^^^
  File "/Users/austinheywood/source/api/venv/lib/python3.11/site-packages/werkzeug/routing/map.py", line 924, in build
    raise BuildError(endpoint, values, method, self)
werkzeug.routing.exceptions.BuildError: Could not build url for endpoint 'signup'. Did you mean 'auth.signup' instead?
2024-10-01 10:45:03,568 ERROR: Exception on /login [GET] [in /Users/austinheywood/source/api/venv/lib/python3.11/site-packages/flask/app.py:838]
Traceback (most recent call last):
  File "/Users/austinheywood/source/api/venv/lib/python3.11/site-packages/flask/app.py", line 1473, in wsgi_app
    response = self.full_dispatch_request()
               ^^^^^^^^^^^^^^^^^^^^^^^^^^^^
  File "/Users/austinheywood/source/api/venv/lib/python3.11/site-packages/flask/app.py", line 882, in full_dispatch_request
    rv = self.handle_user_exception(e)
         ^^^^^^^^^^^^^^^^^^^^^^^^^^^^^
  File "/Users/austinheywood/source/api/venv/lib/python3.11/site-packages/flask/app.py", line 880, in full_dispatch_request
    rv = self.dispatch_request()
         ^^^^^^^^^^^^^^^^^^^^^^^
  File "/Users/austinheywood/source/api/venv/lib/python3.11/site-packages/flask/app.py", line 865, in dispatch_request
    return self.ensure_sync(self.view_functions[rule.endpoint])(**view_args)  # type: ignore[no-any-return]
           ^^^^^^^^^^^^^^^^^^^^^^^^^^^^^^^^^^^^^^^^^^^^^^^^^^^^^^^^^^^^^^^^^
  File "/Users/austinheywood/source/api/app/auth/routes.py", line 25, in login
    return render_template('auth/login.html', title='Sign In')
           ^^^^^^^^^^^^^^^^^^^^^^^^^^^^^^^^^^^^^^^^^^^^^^^^^^^
  File "/Users/austinheywood/source/api/venv/lib/python3.11/site-packages/flask/templating.py", line 150, in render_template
    return _render(app, template, context)
           ^^^^^^^^^^^^^^^^^^^^^^^^^^^^^^^
  File "/Users/austinheywood/source/api/venv/lib/python3.11/site-packages/flask/templating.py", line 131, in _render
    rv = template.render(context)
         ^^^^^^^^^^^^^^^^^^^^^^^^
  File "/Users/austinheywood/source/api/venv/lib/python3.11/site-packages/jinja2/environment.py", line 1304, in render
    self.environment.handle_exception()
  File "/Users/austinheywood/source/api/venv/lib/python3.11/site-packages/jinja2/environment.py", line 939, in handle_exception
    raise rewrite_traceback_stack(source=source)
  File "/Users/austinheywood/source/api/app/templates/auth/login.html", line 1, in top-level template code
    {% extends "base.html" %}
  File "/Users/austinheywood/source/api/app/templates/base.html", line 41, in top-level template code
    {% block content %}{% endblock %}
    ^^^^^^^^^^^^^^^^^^^^^^^^^
  File "/Users/austinheywood/source/api/app/templates/auth/login.html", line 17, in block 'content'
    <p>New User? <a href="{{ url_for('signup') }}">Click to Sign Up!</a></p>
    ^^^^^^^^^^^^^^^^^^^^^^^^^
  File "/Users/austinheywood/source/api/venv/lib/python3.11/site-packages/flask/app.py", line 1084, in url_for
    return self.handle_url_build_error(error, endpoint, values)
           ^^^^^^^^^^^^^^^^^^^^^^^^^^^^^^^^^^^^^^^^^^^^^^^^^^^^
  File "/Users/austinheywood/source/api/venv/lib/python3.11/site-packages/flask/app.py", line 1073, in url_for
    rv = url_adapter.build(  # type: ignore[union-attr]
         ^^^^^^^^^^^^^^^^^^^^^^^^^^^^^^^^^^^^^^^^^^^^^^
  File "/Users/austinheywood/source/api/venv/lib/python3.11/site-packages/werkzeug/routing/map.py", line 924, in build
    raise BuildError(endpoint, values, method, self)
werkzeug.routing.exceptions.BuildError: Could not build url for endpoint 'signup'. Did you mean 'auth.signup' instead?
2024-10-01 10:45:57,756 INFO: RedataPro startup [in /Users/austinheywood/source/api/app/__init__.py:58]
2024-10-01 10:48:13,348 ERROR: Exception on /signup [POST] [in /Users/austinheywood/source/api/venv/lib/python3.11/site-packages/flask/app.py:838]
Traceback (most recent call last):
  File "/Users/austinheywood/source/api/venv/lib/python3.11/site-packages/flask/app.py", line 1473, in wsgi_app
    response = self.full_dispatch_request()
               ^^^^^^^^^^^^^^^^^^^^^^^^^^^^
  File "/Users/austinheywood/source/api/venv/lib/python3.11/site-packages/flask/app.py", line 882, in full_dispatch_request
    rv = self.handle_user_exception(e)
         ^^^^^^^^^^^^^^^^^^^^^^^^^^^^^
  File "/Users/austinheywood/source/api/venv/lib/python3.11/site-packages/flask/app.py", line 880, in full_dispatch_request
    rv = self.dispatch_request()
         ^^^^^^^^^^^^^^^^^^^^^^^
  File "/Users/austinheywood/source/api/venv/lib/python3.11/site-packages/flask/app.py", line 865, in dispatch_request
    return self.ensure_sync(self.view_functions[rule.endpoint])(**view_args)  # type: ignore[no-any-return]
           ^^^^^^^^^^^^^^^^^^^^^^^^^^^^^^^^^^^^^^^^^^^^^^^^^^^^^^^^^^^^^^^^^
  File "/Users/austinheywood/source/api/app/auth/routes.py", line 48, in signup
    return redirect(url_for('login'))
                    ^^^^^^^^^^^^^^^^
  File "/Users/austinheywood/source/api/venv/lib/python3.11/site-packages/flask/helpers.py", line 220, in url_for
    return current_app.url_for(
           ^^^^^^^^^^^^^^^^^^^^
  File "/Users/austinheywood/source/api/venv/lib/python3.11/site-packages/flask/app.py", line 1084, in url_for
    return self.handle_url_build_error(error, endpoint, values)
           ^^^^^^^^^^^^^^^^^^^^^^^^^^^^^^^^^^^^^^^^^^^^^^^^^^^^
  File "/Users/austinheywood/source/api/venv/lib/python3.11/site-packages/flask/app.py", line 1073, in url_for
    rv = url_adapter.build(  # type: ignore[union-attr]
         ^^^^^^^^^^^^^^^^^^^^^^^^^^^^^^^^^^^^^^^^^^^^^^
  File "/Users/austinheywood/source/api/venv/lib/python3.11/site-packages/werkzeug/routing/map.py", line 924, in build
    raise BuildError(endpoint, values, method, self)
werkzeug.routing.exceptions.BuildError: Could not build url for endpoint 'login'. Did you mean 'auth.login' instead?
2024-10-01 10:50:25,117 INFO: RedataPro startup [in /Users/austinheywood/source/api/app/__init__.py:58]
2024-10-01 10:53:23,823 INFO: RedataPro startup [in /Users/austinheywood/source/api/app/__init__.py:58]
2024-10-01 11:04:16,597 INFO: RedataPro startup [in /Users/austinheywood/source/api/app/__init__.py:61]
2024-10-01 11:04:20,700 INFO: RedataPro startup [in /Users/austinheywood/source/api/app/__init__.py:61]
2024-10-01 11:04:35,402 INFO: RedataPro startup [in /Users/austinheywood/source/api/app/__init__.py:61]
2024-10-01 11:05:30,818 INFO: RedataPro startup [in /Users/austinheywood/source/api/app/__init__.py:61]
2024-10-01 11:06:35,926 INFO: RedataPro startup [in /Users/austinheywood/source/api/app/__init__.py:61]
2024-10-01 11:07:07,822 INFO: RedataPro startup [in /Users/austinheywood/source/api/app/__init__.py:61]
2024-10-01 11:07:21,919 INFO: RedataPro startup [in /Users/austinheywood/source/api/app/__init__.py:61]
2024-10-02 23:28:38,390 ERROR: An error occurred: Error fetching data from Black Knight API: Error fetching property data: 404 - {"Locations":[],"Feed":null,"Report":null,"OrderInfo":{"IsValidAddress":true,"SearchId":768041154,"Completed":"2024-10-03 05:28:43Z"}} [in /Users/austinheywood/source/api/app/routes.py:54]
