2024-09-12 23:21:31,207 INFO: RedataPro startup [in /Users/austinheywood/source/api/app/__init__.py:47]
2024-09-12 23:21:48,746 INFO: RedataPro startup [in /Users/austinheywood/source/api/app/__init__.py:47]
2024-09-12 23:21:48,885 INFO: RedataPro startup [in /Users/austinheywood/source/api/app/__init__.py:47]
2024-09-12 23:36:56,306 INFO: RedataPro startup [in /Users/austinheywood/source/api/app/__init__.py:47]
2024-09-12 23:36:58,592 INFO: RedataPro startup [in /Users/austinheywood/source/api/app/__init__.py:47]
2024-09-12 23:37:23,163 INFO: RedataPro startup [in /Users/austinheywood/source/api/app/__init__.py:47]
2024-09-12 23:37:23,165 INFO: RedataPro startup [in /Users/austinheywood/source/api/app/__init__.py:47]
2024-09-12 23:37:23,165 INFO: RedataPro startup [in /Users/austinheywood/source/api/app/__init__.py:47]
2024-09-12 23:37:32,452 INFO: RedataPro startup [in /Users/austinheywood/source/api/app/__init__.py:47]
2024-09-12 23:37:32,453 INFO: RedataPro startup [in /Users/austinheywood/source/api/app/__init__.py:47]
2024-09-12 23:37:32,453 INFO: RedataPro startup [in /Users/austinheywood/source/api/app/__init__.py:47]
2024-09-12 23:37:32,601 INFO: RedataPro startup [in /Users/austinheywood/source/api/app/__init__.py:47]
2024-09-12 23:37:32,602 INFO: RedataPro startup [in /Users/austinheywood/source/api/app/__init__.py:47]
2024-09-12 23:37:32,602 INFO: RedataPro startup [in /Users/austinheywood/source/api/app/__init__.py:47]
2024-09-12 23:39:50,489 INFO: RedataPro startup [in /Users/austinheywood/source/api/app/__init__.py:47]
2024-09-12 23:40:40,374 INFO: RedataPro startup [in /Users/austinheywood/source/api/app/__init__.py:47]
2024-09-12 23:41:08,558 INFO: RedataPro startup [in /Users/austinheywood/source/api/app/__init__.py:47]
2024-09-12 23:41:08,694 INFO: RedataPro startup [in /Users/austinheywood/source/api/app/__init__.py:47]
2024-09-12 23:41:59,566 INFO: RedataPro startup [in /Users/austinheywood/source/api/app/__init__.py:50]
2024-09-12 23:42:20,028 INFO: RedataPro startup [in /Users/austinheywood/source/api/app/__init__.py:50]
2024-09-12 23:43:13,977 INFO: RedataPro startup [in /Users/austinheywood/source/api/app/__init__.py:50]
2024-09-12 23:43:19,134 INFO: RedataPro startup [in /Users/austinheywood/source/api/app/__init__.py:50]
2024-09-12 23:43:19,266 INFO: RedataPro startup [in /Users/austinheywood/source/api/app/__init__.py:50]
2024-09-12 23:45:26,154 INFO: RedataPro startup [in /Users/austinheywood/source/api/app/__init__.py:50]
2024-09-12 23:45:56,902 INFO: RedataPro startup [in /Users/austinheywood/source/api/app/__init__.py:50]
2024-09-12 23:45:57,036 INFO: RedataPro startup [in /Users/austinheywood/source/api/app/__init__.py:50]
2024-09-13 00:12:14,666 INFO: RedataPro startup [in /Users/austinheywood/source/api/app/__init__.py:50]
2024-09-13 00:12:14,817 INFO: RedataPro startup [in /Users/austinheywood/source/api/app/__init__.py:50]
2024-09-13 00:12:24,375 ERROR: An error occurred: Invalid API provider selected [in /Users/austinheywood/source/api/app/routes.py:30]
2024-09-13 00:12:38,959 ERROR: An error occurred: Invalid URL 'None': No scheme supplied. Perhaps you meant https://None? [in /Users/austinheywood/source/api/app/routes.py:30]
2024-09-13 00:14:27,836 INFO: RedataPro startup [in /Users/austinheywood/source/api/app/__init__.py:50]
2024-09-13 00:14:30,072 INFO: RedataPro startup [in /Users/austinheywood/source/api/app/__init__.py:50]
2024-09-13 00:14:52,556 INFO: RedataPro startup [in /Users/austinheywood/source/api/app/__init__.py:50]
2024-09-13 00:14:52,692 INFO: RedataPro startup [in /Users/austinheywood/source/api/app/__init__.py:50]
2024-09-13 00:14:55,692 ERROR: An error occurred: Invalid URL 'None': No scheme supplied. Perhaps you meant https://None? [in /Users/austinheywood/source/api/app/routes.py:31]
2024-09-13 00:15:07,805 ERROR: An error occurred: Invalid URL 'None': No scheme supplied. Perhaps you meant https://None? [in /Users/austinheywood/source/api/app/routes.py:31]
2024-09-13 00:15:34,541 INFO: RedataPro startup [in /Users/austinheywood/source/api/app/__init__.py:50]
2024-09-13 00:15:49,990 INFO: RedataPro startup [in /Users/austinheywood/source/api/app/__init__.py:50]
2024-09-13 00:16:01,978 INFO: RedataPro startup [in /Users/austinheywood/source/api/app/__init__.py:50]
2024-09-13 00:16:02,117 INFO: RedataPro startup [in /Users/austinheywood/source/api/app/__init__.py:50]
2024-09-13 00:16:05,831 ERROR: An error occurred: Invalid URL 'None': No scheme supplied. Perhaps you meant https://None? [in /Users/austinheywood/source/api/app/routes.py:31]
2024-09-13 00:16:14,967 ERROR: An error occurred: Black Knight API configuration error: BLACKKNIGHT_API_URL is not set in the configuration [in /Users/austinheywood/source/api/app/routes.py:31]
2024-09-13 00:19:07,833 INFO: RedataPro startup [in /Users/austinheywood/source/api/app/__init__.py:50]
2024-09-13 00:19:07,980 INFO: RedataPro startup [in /Users/austinheywood/source/api/app/__init__.py:50]
2024-09-16 22:41:46,875 ERROR: An error occurred: Error fetching data from Black Knight API: Error fetching property data: 404 - {"Locations":[],"Feed":null,"Report":null,"OrderInfo":{"IsValidAddress":false,"SearchId":756931114,"Completed":"2024-09-17 05:41:58Z"}} [in /Users/austinheywood/source/api/app/routes.py:31]
2024-09-16 22:58:20,824 INFO: RedataPro startup [in /Users/austinheywood/source/api/app/__init__.py:50]
2024-09-16 22:58:22,150 INFO: RedataPro startup [in /Users/austinheywood/source/api/app/__init__.py:50]
2024-09-16 22:59:53,616 INFO: RedataPro startup [in /Users/austinheywood/source/api/app/__init__.py:50]
2024-09-16 23:00:07,052 INFO: RedataPro startup [in /Users/austinheywood/source/api/app/__init__.py:50]
2024-09-16 23:00:31,830 INFO: RedataPro startup [in /Users/austinheywood/source/api/app/__init__.py:50]
2024-09-16 23:00:31,971 INFO: RedataPro startup [in /Users/austinheywood/source/api/app/__init__.py:50]
2024-09-30 21:30:13,765 INFO: RedataPro startup [in /Users/austinheywood/source/api/app/__init__.py:50]
2024-10-01 10:02:09,898 INFO: RedataPro startup [in /Users/austinheywood/source/api/app/__init__.py:58]
2024-10-01 10:02:50,038 INFO: RedataPro startup [in /Users/austinheywood/source/api/app/__init__.py:58]
2024-10-01 10:02:57,732 INFO: RedataPro startup [in /Users/austinheywood/source/api/app/__init__.py:58]
2024-10-01 10:03:56,661 INFO: RedataPro startup [in /Users/austinheywood/source/api/app/__init__.py:58]
2024-10-01 10:03:58,227 ERROR: Exception on / [POST] [in /Users/austinheywood/source/api/venv/lib/python3.11/site-packages/flask/app.py:838]
Traceback (most recent call last):
  File "/Users/austinheywood/source/api/venv/lib/python3.11/site-packages/flask/app.py", line 1473, in wsgi_app
    response = self.full_dispatch_request()
               ^^^^^^^^^^^^^^^^^^^^^^^^^^^^
  File "/Users/austinheywood/source/api/venv/lib/python3.11/site-packages/flask/app.py", line 882, in full_dispatch_request
    rv = self.handle_user_exception(e)
         ^^^^^^^^^^^^^^^^^^^^^^^^^^^^^
  File "/Users/austinheywood/source/api/venv/lib/python3.11/site-packages/flask/app.py", line 880, in full_dispatch_request
    rv = self.dispatch_request()
         ^^^^^^^^^^^^^^^^^^^^^^^
  File "/Users/austinheywood/source/api/venv/lib/python3.11/site-packages/flask/app.py", line 865, in dispatch_request
    return self.ensure_sync(self.view_functions[rule.endpoint])(**view_args)  # type: ignore[no-any-return]
           ^^^^^^^^^^^^^^^^^^^^^^^^^^^^^^^^^^^^^^^^^^^^^^^^^^^^^^^^^^^^^^^^^
  File "/Users/austinheywood/source/api/venv/lib/python3.11/site-packages/flask_login/utils.py", line 284, in decorated_view
    elif not current_user.is_authenticated:
             ^^^^^^^^^^^^^^^^^^^^^^^^^^^^^
  File "/Users/austinheywood/source/api/venv/lib/python3.11/site-packages/werkzeug/local.py", line 318, in __get__
    obj = instance._get_current_object()
          ^^^^^^^^^^^^^^^^^^^^^^^^^^^^^^
  File "/Users/austinheywood/source/api/venv/lib/python3.11/site-packages/werkzeug/local.py", line 526, in _get_current_object
    return get_name(local())
                    ^^^^^^^
  File "/Users/austinheywood/source/api/venv/lib/python3.11/site-packages/flask_login/utils.py", line 25, in <lambda>
    current_user = LocalProxy(lambda: _get_user())
                                      ^^^^^^^^^^^
  File "/Users/austinheywood/source/api/venv/lib/python3.11/site-packages/flask_login/utils.py", line 370, in _get_user
    current_app.login_manager._load_user()
  File "/Users/austinheywood/source/api/venv/lib/python3.11/site-packages/flask_login/login_manager.py", line 347, in _load_user
    raise Exception(
Exception: Missing user_loader or request_loader. Refer to http://flask-login.readthedocs.io/#how-it-works for more info.
